[32m2025-02-08 09:53:18 +0100[0m - dagster - [34mDEBUG[0m - trip_update_job - fa81c045-2858-4755-9af7-b0db97f4402d - 43090 - LOGS_CAPTURED - Started capturing logs in process (pid: 43090).
[32m2025-02-08 09:53:18 +0100[0m - dagster - [34mDEBUG[0m - trip_update_job - fa81c045-2858-4755-9af7-b0db97f4402d - 43090 - manhattan_map - STEP_START - Started execution of step "manhattan_map".
[32m2025-02-08 09:54:39 +0100[0m - dagster - [34mERROR[0m - [31mtrip_update_job - fa81c045-2858-4755-9af7-b0db97f4402d - 43090 - manhattan_map - STEP_FAILURE - Execution of step "manhattan_map" failed.

dagster._core.errors.DagsterExecutionStepExecutionError: Error occurred while executing op "manhattan_map"::

ValueError: Transform failed with error code 525: Mapbox error.

Stack Trace:
  File "/Users/alejandrogonzalezbueno/Projects/dagster-and-dbt/.venv/lib/python3.11/site-packages/dagster/_core/execution/plan/utils.py", line 56, in op_execution_error_boundary
    yield
  File "/Users/alejandrogonzalezbueno/Projects/dagster-and-dbt/.venv/lib/python3.11/site-packages/dagster/_utils/__init__.py", line 480, in iterate_with_context
    next_output = next(iterator)
                  ^^^^^^^^^^^^^^
  File "/Users/alejandrogonzalezbueno/Projects/dagster-and-dbt/.venv/lib/python3.11/site-packages/dagster/_core/execution/plan/compute_generator.py", line 127, in _coerce_op_compute_fn_to_iterator
    result = invoke_compute_fn(
             ^^^^^^^^^^^^^^^^^^
  File "/Users/alejandrogonzalezbueno/Projects/dagster-and-dbt/.venv/lib/python3.11/site-packages/dagster/_core/execution/plan/compute_generator.py", line 115, in invoke_compute_fn
    return fn(context, **args_to_pass) if context_arg_provided else fn(**args_to_pass)
                                                                    ^^^^^^^^^^^^^^^^^^
  File "/Users/alejandrogonzalezbueno/Projects/dagster-and-dbt/dagster_university/assets/metrics.py", line 125, in manhattan_map
    pio.write_image(fig, output_file)
  File "/Users/alejandrogonzalezbueno/Projects/dagster-and-dbt/.venv/lib/python3.11/site-packages/plotly/io/_kaleido.py", line 266, in write_image
    img_data = to_image(
               ^^^^^^^^^
  File "/Users/alejandrogonzalezbueno/Projects/dagster-and-dbt/.venv/lib/python3.11/site-packages/plotly/io/_kaleido.py", line 143, in to_image
    img_bytes = scope.transform(
                ^^^^^^^^^^^^^^^^
  File "/Users/alejandrogonzalezbueno/Projects/dagster-and-dbt/.venv/lib/python3.11/site-packages/kaleido/scopes/plotly.py", line 161, in transform
    raise ValueError(
[0m
